Workbook

Sheet Cover
B2: TEST REPORT DOCUMENT
A4: Project Name | B4: Xây dựng nền tảng đặt vé xe trực tuyến theo kiến trúc Microservices | E4: Creator | F4: Nhóm PBL6 – 23NH11
A5: Project Code | B5: PBL6 | E5: Issue Date | F5: 46323
A6: Document Code | B6: =B5&"_"&"API_TestReport"&"_"&"v"&F6 -> PBL6_API_TestReport_v1.1 | E6: Version | F6: 1.1
A9: Record of change
A10: Effective Date | B10: Version | C10: Change Item | D10: *A,D,M | E10: Change description | F10: Reference
A11: 46323 | B11: 1.0 | C11: Toàn bộ tài liệu | D11: A | E11: Tạo mới báo cáo kiểm thử API (Postman): 152 test case / 11 module, xây dựng từ SRS PBL6. | F11: SRS-PBL6.docx (mục 3.8–3.14, 5, 6, 7.4–7.5, 10, 11.1)
A12: 46323 | B12: 1.1 | C12: Cấu trúc workbook | D12: M | E12: Gộp 11 sheet module (F1–F11) thành 6 sheet theo service (Auth, Trip, Booking, Payment, Notification, Report); cập nhật Test Cases và Test Statistics. Giữ nguyên 152 test case và Test Case ID. | F12: SRS-PBL6.docx (kiến trúc Microservices)

Sheet Test Cases
D1: TEST CASE LIST
B3: Project Name | D3: =Cover!B4 -> Xây dựng nền tảng đặt vé xe trực tuyến theo kiến trúc Microservices
B4: Project Code | D4: =Cover!B5 -> PBL6
B5: Test Environment Setup Description | D5: 1. Server: Backend Microservices (Auth, Trip, Booking, Payment, Notification, Report) chạy qua API Gateway, HTTPS, JSON UTF-8 2. Database: CSDL của từng service; dữ liệu test tách theo nhà xe A/B, không dùng dữ liệu thật 3. Công cụ: Postman (Collection + Environment + Collection Runner), Newman để chạy CLI/CI 4. Tài khoản test: Customer 1/2, Operator Staff A/B, Finance Staff A, Driver (được/không được phân công), Admin 5. Cổng thanh toán sandbox/mock gửi được webhook (đúng/sai chữ ký, sai số tiền, lặp, đến trễ); Notification Provider mock (giả lập được lỗi) 6. Biến môi trường: baseUrl, accessToken, refreshToken, tripId, seatIds, holdId, bookingId, paymentId, ticketId Lưu ý: SRS (mục 7.4) để chi tiết endpoint trong OpenAPI riêng, nên đường dẫn endpoint trong các test case là đường dẫn giả định theo nghiệp vụ; cần đối chiếu và chỉnh theo OpenAPI thực tế.
B8: No | C8: Function Name | D8: Sheet Name | E8: Description | F8: Pre-Condition
B9: 1 | C9: Đăng ký & kích hoạt tài khoản | D9: Auth_Service | E9: FR-IAM-001/002; AC-AUTH-001/003/004 (7 TC) | F9: Chưa có tài khoản với email/SĐT test.
B10: 2 | C10: Đăng nhập | D10: Auth_Service | E10: FR-IAM-003/007; AC-AUTH-005/006; NFR-SEC-005 (5 TC) | F10: Có tài khoản active.
B11: 3 | C11: Refresh phiên & đăng xuất | D11: Auth_Service | E11: FR-IAM-004; AC-AUTH-007/008; NFR-SEC-003 (3 TC) | F11: Đã đăng nhập, có refreshToken.
B12: 4 | C12: Quên & đặt lại mật khẩu | D12: Auth_Service | E12: FR-IAM-005; AC-AUTH-009 (3 TC) | F12: -
B13: 5 | C13: Hồ sơ cá nhân | D13: Auth_Service | E13: FR-IAM-006; AC-PROFILE-001 (4 TC) | F13: Customer đã đăng nhập (có accessToken).
B14: 6 | C14: Quản lý người dùng & tổ chức | D14: Auth_Service | E14: FR-IAM-008/009; FR-ADMIN-001; AC-ADMIN-001/002 (5 TC) | F14: Admin đã đăng nhập.
B15: 7 | C15: Hợp đồng API chung | D15: Auth_Service | E15: SRS §7.4, §7.5, BR-BOOK-006, BR-DATA-002 (5 TC) | F15: Có Postman Environment hợp lệ.
B16: 8 | C16: Bảo mật API | D16: Auth_Service | E16: AUTHZ-001..005; NFR-SEC-004/007; AC-SEC-001/002 (6 TC) | F16: -
B17: 9 | C17: Tìm kiếm chuyến xe | D17: Trip_Service | E17: FR-SEARCH-001/002; AC-SEARCH-001/003 (4 TC) | F17: Có dữ liệu chuyến xe gồm cả chuyến còn bán và không còn bán.
B18: 10 | C18: Lọc, sắp xếp & phân trang | D18: Trip_Service | E18: FR-SEARCH-003/004; AC-SEARCH-002 (4 TC) | F18: Có nhiều chuyến phù hợp cùng tuyến.
B19: 11 | C19: Chi tiết chuyến xe & ghế trống | D19: Trip_Service | E19: FR-SEARCH-005/006; NFR-SEC-007 (4 TC) | F19: Có chuyến T1.
B20: 12 | C20: Thông tin nhà xe | D20: Trip_Service | E20: FR-OPS-001/011; BR-TENANT-002; AC-AUTH-002 (3 TC) | F20: Operator Staff của nhà xe A đã đăng nhập.
... B41: 33 | C41: Báo cáo & xuất dữ liệu | D41: Report_Service | E41: FR-REPORT-001..003; AC-REPORT-001/002 (4 TC) | F41: Admin đã đăng nhập.

Sheet Test Statistics
B1: TEST STATISTICS
B3: Project Name | C3: =Cover!B4 -> Xây dựng nền tảng đặt vé xe trực tuyến theo kiến trúc Microservices | E3: Creator | H3: Nhóm PBL6 – 23NH11
B4: Project Code | C4: =Cover!B5 -> PBL6 | E4: Reviewer/Approver
B5: Document Code | C5: =C4&"_"&"API Test Report"&"_"&"v"&Cover!F6 -> PBL6_API Test Report_v1.1 | E5: Issue Date | H5: =Cover!F5 -> 46323
B6: Notes | C6: Release 1 gồm 6 service kiểm thử API bằng Postman (152 test case): Auth Service – xác thực, hồ sơ, quản lý người dùng & tổ chức, hợp đồng API chung & bảo mật API; Trip Service – tìm kiếm & xem chuyến xe, quản lý nhà xe (xe, tài xế, tuyến), tạo/công bố/vận hành/hủy chuyến; Booking Service – giữ ghế & đặt chỗ, hủy vé/hoàn tiền/đổi vé, vé điện tử & check-in, khuyến mãi, đánh giá; Payment Service – thanh toán, webhook, settlement; Notification Service – thông báo; Report Service – tra cứu giao dịch, kiểm toán, khiếu nại, báo cáo & xuất dữ liệu. Kết quả Round 1–3 hiện ở trạng thái Pending, chưa thực thi.
B10: No | C10: Module code | D10: Passed | E10: Failed | F10: Pending | G10: N/A | H10: Number of test cases
B11: 1 | C11: =Auth_Service!B2 -> Auth Service | D11: =Auth_Service!B6 -> 0 | E11: =Auth_Service!C6 -> 0 | F11: =Auth_Service!D6 -> 38 | G11: =Auth_Service!E6 -> 0 | H11: =Auth_Service!B4 -> 38
B12: 2 | C12: =Trip_Service!B2 -> Trip Service | D12: =Trip_Service!B6 -> 0 | E12: =Trip_Service!C6 -> 0 | F12: =Trip_Service!D6 -> 37 | G12: =Trip_Service!E6 -> 0 | H12: =Trip_Service!B4 -> 37
B13: 3 | C13: =Booking_Service!B2 -> Booking Service | D13: =Booking_Service!B6 -> 0 | E13: =Booking_Service!C6 -> 0 | F13: =Booking_Service!D6 -> 54 | G13: =Booking_Service!E6 -> 0 | H13: =Booking_Service!B4 -> 54
B14: 4 | C14: =Payment_Service!B2 -> Payment Service | D14: =Payment_Service!B6 -> 0 | E14: =Payment_Service!C6 -> 0 | F14: =Payment_Service!D6 -> 13 | G14: =Payment_Service!E6 -> 0 | H14: =Payment_Service!B4 -> 13
B15: 5 | C15: =Notification_Service!B2 -> Notification Service | D15: =Notification_Service!B6 -> 0 | E15: =Notification_Service!C6 -> 0 | F15: =Notification_Service!D6 -> 3 | G15: =Notification_Service!E6 -> 0 | H15: =Notification_Service!B4 -> 3
B16: 6 | C16: =Report_Service!B2 -> Report Service | D16: =Report_Service!B6 -> 0 | E16: =Report_Service!C6 -> 0 | F16: =Report_Service!D6 -> 7 | G16: =Report_Service!E6 -> 0 | H16: =Report_Service!B4 -> 7
C18: Sub total | D18: =SUM(D11:D16) -> 0 | E18: =SUM(E11:E16) -> 0 | F18: =SUM(F11:F16) -> 152 | G18: =SUM(G11:G16) -> 0 | H18: =SUM(H11:H16) -> 152
C20: Test coverage | E20: =(D18+E18)*100/(H18-G18) -> 0 | F20: %
C21: Test successful coverage | E21: =D18*100/(H18-G18) -> 0 | F21: %

Sheet Auth_Service
A2: Feature | B2: Auth Service | R2: Passed
A3: Test requirement | B3: FR-IAM-001..009, FR-ADMIN-001, AC-AUTH-001..009, AC-PROFILE-001, AC-ADMIN-001/002, AC-SEC-001/002, AUTHZ-001..008, NFR-SEC-003..007, SRS §7.4–7.5, §11.1: đăng ký, kích hoạt, đăng nhập, refresh/đăng xuất, quên mật khẩu, hồ sơ, quản lý người dùng & tổ chức, hợp đồng API chung và bảo mật API. | R3: Failed
A4: Number of TCs | B4: =COUNTA(B11:B1000) -> 38 | R4: Pending
A5: Testing Round | B5: Passed | C5: Failed | D5: Pending | E5: N/A | R5: N/A
A6: Round 1 | B6: =COUNTIF($F$11:$F$1000,B$5) -> 0 | C6: =COUNTIF($F$11:$F$1000,C$5) -> 0 | D6: =COUNTIF($F$11:$F$1000,D$5) -> 38 | E6: =COUNTIF($F$11:$F$1000,E$5) -> 0
A7: Round 2 | B7: =COUNTIF($I$11:$I$1000,B$5) -> 0 | C7: =COUNTIF($I$11:$I$1000,C$5) -> 0 | D7: =COUNTIF($I$11:$I$1000,D$5) -> 38 | E7: =COUNTIF($I$11:$I$1000,E$5) -> 0
A8: Round 3 | B8: =COUNTIF($L$11:$L$1000,B$5) -> 0 | C8: =COUNTIF($L$11:$L$1000,C$5) -> 0 | D8: =COUNTIF($L$11:$L$1000,D$5) -> 38 | E8: =COUNTIF($L$11:$L$1000,E$5) -> 0
A10: Test Case ID | B10: Test Case Description | C10: Test Case Procedure | D10: Expected Results | E10: Pre-conditions | F10: Round 1 | G10: Test date | H10: Tester | I10: Round 2 | J10: Test date | K10: Tester | L10: Round 3 | M10: Test date | N10: Tester | O10: Note
A11: Đăng ký & kích hoạt tài khoản
A12: AUTH-01 | B12: Đăng ký tài khoản hợp lệ | C12: 1. POST /auth/register {fullName, email, phone, password hợp lệ} 2. Kiểm tra status + body | D12: 201 Created; user ở trạng thái chưa kích hoạt; hệ thống gửi OTP/email xác minh; body không chứa mật khẩu. | E12: Email/SĐT chưa tồn tại. | F12: Pending | I12: Pending | L12: Pending
A13: AUTH-02 | B13: Đăng ký với email đã thuộc tài khoản đang hoạt động | C13: 1. POST /auth/register với email đã tồn tại 2. Kiểm tra DB/API số user theo email | D13: Bị từ chối bằng lỗi 4xx an toàn; không tạo user thứ hai (AC-AUTH-001). | E13: Email đã thuộc tài khoản active. | F13: Pending | I13: Pending | L13: Pending
A14: AUTH-03 | B14: Đăng ký với số điện thoại đã tồn tại | C14: 1. POST /auth/register với phone đã tồn tại | D14: Bị từ chối bằng lỗi 4xx an toàn; không tạo user thứ hai. | E14: SĐT đã thuộc tài khoản active. | F14: Pending | I14: Pending | L14: Pending
A15: AUTH-04 | B15: Đăng ký với dữ liệu không hợp lệ | C15: 1. POST /auth/register lần lượt: thiếu trường bắt buộc / email sai định dạng / SĐT sai / mật khẩu yếu (data-driven bằng Collection Runner) | D15: 400 VALIDATION_ERROR; details liệt kê field lỗi + lý do an toàn; không tạo user. | E15: - | F15: Pending | I15: Pending | L15: Pending
A16: AUTH-05 | B16: Xác minh bằng OTP/token đúng | C16: 1. Đăng ký tài khoản 2. POST /auth/verify {identifier, otp đúng} 3. POST /auth/login | D16: Xác minh thành công; user được kích hoạt và đăng nhập được (AC-AUTH-003). | E16: Có tài khoản vừa đăng ký, chưa kích hoạt. | F16: Pending | I16: Pending | L16: Pending
A17: AUTH-06 | B17: Xác minh bằng OTP sai / hết hạn | C17: 1. POST /auth/verify với OTP sai 2. POST /auth/verify với OTP đã hết hạn 3. POST /auth/login | D17: Trả lỗi; user vẫn chưa hoạt động, không đăng nhập được; cho phép gửi lại OTP theo giới hạn (AC-AUTH-004). | E17: Có tài khoản chưa kích hoạt. | F17: Pending | I17: Pending | L17: Pending
A18: AUTH-07 | B18: Gửi lại OTP vượt giới hạn tần suất | C18: 1. POST /auth/resend-otp liên tiếp vượt ngưỡng cấu hình | D18: 429 RATE_LIMITED kèm header Retry-After (NFR-SEC-004). | E18: Có tài khoản chưa kích hoạt. | F18: Pending | I18: Pending | L18: Pending
A19: Đăng nhập
A20: AUTH-08 | B20: Đăng nhập bằng email đúng | C20: 1. POST /auth/login {email, password đúng} 2. Giải mã accessToken | D20: 200; trả accessToken + refreshToken; token chứa đúng vai trò và phạm vi nhà xe (AC-AUTH-005). | E20: Tài khoản active. | F20: Pending | I20: Pending | L20: Pending
A21: AUTH-09 | B21: Đăng nhập bằng số điện thoại đúng | C21: 1. POST /auth/login {phone, password đúng} | D21: 200; trả accessToken + refreshToken. | E21: Tài khoản active. | F21: Pending | I21: Pending | L21: Pending
A22: AUTH-10 | B22: Đăng nhập sai mật khẩu | C22: 1. POST /auth/login {email, password sai} | D22: 401; không cấp token; thông báo lỗi không lộ thông tin nhạy cảm. | E22: Tài khoản active. | F22: Pending | I22: Pending | L22: Pending
A23: AUTH-11 | B23: Đăng nhập tài khoản chưa kích hoạt / bị khóa | C23: 1. POST /auth/login với tài khoản chưa kích hoạt 2. POST /auth/login với tài khoản bị Admin khóa | D23: Bị từ chối; không cấp token. | E23: Có tài khoản chưa kích hoạt và tài khoản bị khóa. | F23: Pending | I23: Pending | L23: Pending
A24: AUTH-12 | B24: Đăng nhập sai liên tiếp vượt ngưỡng (5 lần) | C24: 1. POST /auth/login sai mật khẩu 5 lần liên tiếp 2. POST /auth/login lần 6 với mật khẩu đúng | D24: Tài khoản/định danh bị khóa hoặc làm chậm tối thiểu 15 phút; có nhật ký kiểm toán bảo mật (NFR-SEC-005, AC-AUTH-006). | E24: Tài khoản active, chưa bị khóa. | F24: Pending | I24: Pending | L24: Pending
A25: Refresh phiên & đăng xuất
A26: AUTH-13 | B26: Refresh token hợp lệ (xoay vòng) | C26: 1. POST /auth/refresh {refreshToken} 2. Dùng lại refreshToken cũ để refresh lần nữa | D26: Lần 1: cấp token mới. Lần 2: refresh token cũ bị từ chối (AC-AUTH-007). | E26: Có refreshToken hợp lệ. | F26: Pending | I26: Pending | L26: Pending
A27: AUTH-14 | B27: Đăng xuất thu hồi refresh token | C27: 1. POST /auth/logout 2. POST /auth/refresh bằng refreshToken vừa bị thu hồi | D27: Đăng xuất thành công; refresh bằng token đã thu hồi bị từ chối, không cấp phiên mới (AC-AUTH-008). | E27: Đã đăng nhập. | F27: Pending | I27: Pending | L27: Pending
A28: AUTH-15 | B28: Gọi API bảo vệ khi không có / hết hạn accessToken | C28: 1. GET /profile không gửi token 2. GET /profile với accessToken đã hết hạn (>15 phút) | D28: 401 AUTHENTICATION_REQUIRED (NFR-SEC-003, AUTHZ-001). | E28: Có accessToken hết hạn. | F28: Pending | I28: Pending | L28: Pending
A29: Quên & đặt lại mật khẩu
A30: AUTH-16 | B30: Yêu cầu reset mật khẩu không lộ việc tài khoản tồn tại | C30: 1. POST /auth/forgot-password với email tồn tại 2. POST /auth/forgot-password với email không tồn tại 3. So sánh status + body 2 phản hồi | D30: Hai phản hồi giống nhau về status và nội dung, không tiết lộ tài khoản có tồn tại hay không (AC-AUTH-009). | E30: 1 email đã đăng ký, 1 email chưa đăng ký. | F30: Pending | I30: Pending | L30: Pending
A31: AUTH-17 | B31: Đặt lại mật khẩu bằng token/OTP hợp lệ | C31: 1. POST /auth/reset-password {token/otp hợp lệ, newPassword} 2. Đăng nhập bằng mật khẩu mới và mật khẩu cũ | D31: Đổi mật khẩu thành công; mật khẩu mới đăng nhập được, mật khẩu cũ bị từ chối. | E31: Đã yêu cầu reset, có token/OTP còn hạn. | F31: Pending | I31: Pending | L31: Pending
A32: AUTH-18 | B32: Đặt lại mật khẩu bằng token/OTP sai hoặc hết hạn | C32: 1. POST /auth/reset-password với token sai 2. POST /auth/reset-password với token hết hạn | D32: Bị từ chối; mật khẩu không thay đổi. | E32: - | F32: Pending | I32: Pending | L32: Pending
A33: Hồ sơ cá nhân
A34: PRF-01 | B34: Xem hồ sơ của chính mình | C34: 1. GET /profile | D34: 200; trả thông tin hồ sơ của đúng người dùng đang đăng nhập; không có mật khẩu/hash. | E34: Customer đã đăng nhập (có accessToken). | F34: Pending | I34: Pending | L34: Pending
A35: PRF-02 | B35: Cập nhật họ tên | C35: 1. PUT /profile {fullName mới} 2. GET /profile | D35: 200; họ tên được cập nhật. | E35: Customer đã đăng nhập (có accessToken). | F35: Pending | I35: Pending | L35: Pending
A36: PRF-03 | B36: Đổi email/SĐT phải xác minh lại | C36: 1. PUT /profile {email mới} 2. GET /profile trước khi xác minh | D36: Email mới chỉ có hiệu lực sau khi xác minh; trước đó hồ sơ vẫn giữ email cũ (AC-PROFILE-001). | E36: Customer đã đăng nhập (có accessToken). | F36: Pending | I36: Pending | L36: Pending
A37: PRF-04 | B37: Xác minh email mới thất bại | C37: 1. Đổi email 2. Xác minh với OTP sai 3. GET /profile | D37: Xác minh lỗi; giá trị cũ vẫn có hiệu lực (AC-PROFILE-001). | E37: Customer đã đăng nhập (có accessToken). | F37: Pending | I37: Pending | L37: Pending
A38: Quản lý người dùng & tổ chức
A39: ADM-01 | B39: Khóa / mở khóa người dùng | C39: 1. PATCH /admin/users/{id}/lock 2. Đăng nhập bằng user bị khóa 3. PATCH unlock, đăng nhập lại | D39: Bị khóa: không đăng nhập được, phiên bị thu hồi; mở khóa: đăng nhập được; có nhật ký kiểm toán. | E39: Admin đã đăng nhập. | F39: Pending | I39: Pending | L39: Pending
A40: ADM-02 | B40: Gán/bỏ vai trò và tư cách thành viên nhà xe | C40: 1. POST /admin/users/{id}/roles 2. DELETE role 3. GET audit | D40: Thay đổi đúng phạm vi; phiên được thu hồi khi cần; có audit event (AC-ADMIN-001, AUTHZ-006). | E40: Admin đã đăng nhập. | F40: Pending | I40: Pending | L40: Pending
A41: ADM-03 | B41: Tạo tổ chức nhà xe và thành viên | C41: 1. POST /admin/operators 2. POST /admin/operators/{id}/members (staff, driver) | D41: 201; tổ chức và membership được tạo đúng (FR-IAM-009). | E41: Admin đã đăng nhập. | F41: Pending | I41: Pending | L41: Pending
A42: ADM-04 | B42: Gỡ quyền quản trị viên cuối cùng | C42: 1. DELETE role ADMIN của admin duy nhất còn lại | D42: Bị từ chối; quyền giữ nguyên (AC-ADMIN-002). | E42: Hệ thống chỉ còn 1 Admin. | F42: Pending | I42: Pending | L42: Pending
...

Sheet Trip_Service
A2: Feature | B2: Trip Service | R2: Passed
A3: Test requirement | B3: FR-SEARCH-001..006, FR-OPS-001..011, BR-TRIP-001..006, BR-TENANT-001/002, BR-DATA-004, AC-SEARCH-001..003, AC-OPS-001..006, AC-TRIP-001/002, AC-AUTH-002, NFR-SEC-007, trạng thái Trip (chương 6.7): tìm kiếm, chi tiết chuyến, quản lý nhà xe/xe/tài xế/tuyến, tạo - công bố - vận hành - hủy chuyến. | R3: Failed
A4: Number of TCs | B4: =COUNTA(B11:B1000) -> 37 | R4: Pending
A5: Testing Round | B5: Passed | C5: Failed | D5: Pending | E5: N/A | R5: N/A
A6: Round 1 | B6: =COUNTIF($F$11:$F$1000,B$5) -> 0 | C6: =COUNTIF($F$11:$F$1000,C$5) -> 0 | D6: =COUNTIF($F$11:$F$1000,D$5) -> 37 | E6: =COUNTIF($F$11:$F$1000,E$5) -> 0
A7: Round 2 | B7: =COUNTIF($I$11:$I$1000,B$5) -> 0 | C7: =COUNTIF($I$11:$I$1000,C$5) -> 0 | D7: =COUNTIF($I$11:$I$1000,D$5) -> 37 | E7: =COUNTIF($I$11:$I$1000,E$5) -> 0
A8: Round 3 | B8: =COUNTIF($L$11:$L$1000,B$5) -> 0 | C8: =COUNTIF($L$11:$L$1000,C$5) -> 0 | D8: =COUNTIF($L$11:$L$1000,D$5) -> 37 | E8: =COUNTIF($L$11:$L$1000,E$5) -> 0
A10: Test Case ID | B10: Test Case Description | C10: Test Case Procedure | D10: Expected Results | E10: Pre-conditions | F10: Round 1 | G10: Test date | H10: Tester | I10: Round 2 | J10: Test date | K10: Tester | L10: Round 3 | M10: Test date | N10: Tester | O10: Note
A11: Tìm kiếm chuyến xe
A12: SRCH-01 | B12: Tìm chuyến hợp lệ (khách vãng lai, không token) | C12: 1. GET /trips/search?from=&to=&date=&passengers=1 (không gửi token) | D12: 200; danh sách chuyến đúng điểm đi/đến/ngày; có phân trang và tổng số kết quả. | E12: Có chuyến phù hợp. | F12: Pending | I12: Pending | L12: Pending
A13: SRCH-02 | B13: Chuyến không còn bán không xuất hiện trong kết quả | C13: 1. Tìm chuyến theo tuyến/ngày có chuyến CANCELLED/DEPARTED/đóng bán 2. Đối chiếu danh sách | D13: Chỉ trả các chuyến còn bán được; chuyến không còn bán không xuất hiện (AC-SEARCH-001). | E13: Có chuyến SCHEDULED và chuyến CANCELLED cùng tuyến. | F13: Pending | I13: Pending | L13: Pending
A14: SRCH-03 | B14: Tìm không có kết quả | C14: 1. GET /trips/search với tuyến/ngày không có chuyến | D14: 200; danh sách rỗng, total = 0; không trả lỗi hệ thống (AC-SEARCH-003). | E14: - | F14: Pending | I14: Pending | L14: Pending
A15: SRCH-04 | B15: Tìm với tham số không hợp lệ | C15: 1. GET /trips/search lần lượt: thiếu điểm đi/đến, ngày sai định dạng, passengers ≤ 0, điểm đi trùng điểm đến | D15: 400 VALIDATION_ERROR kèm danh sách field lỗi. | E15: - | F15: Pending | I15: Pending | L15: Pending
A16: Lọc, sắp xếp & phân trang
A17: SRCH-05 | B17: Lọc kết quả theo tiêu chí | C17: 1. GET /trips/search kèm lần lượt: minPrice/maxPrice, giờ đi, operatorId, loại xe, điểm đón/trả, tiện nghi, đánh giá tối thiểu | D17: Mọi chuyến trả về đều thỏa tiêu chí lọc. | E17: Có nhiều chuyến phù hợp. | F17: Pending | I17: Pending | L17: Pending
A18: SRCH-06 | B18: Sắp xếp kết quả | C18: 1. GET /trips/search?sort=price,asc|desc 2. Lặp với giờ khởi hành, thời lượng, đánh giá | D18: Danh sách đúng thứ tự theo tiêu chí và chiều sắp xếp. | E18: Có nhiều chuyến phù hợp. | F18: Pending | I18: Pending | L18: Pending
A19: SRCH-07 | B19: Phân trang | C19: 1. GET /trips/search?page=1&size=5 2. GET page=2 3. So sánh total, không trùng/thiếu phần tử | D19: Trả đúng số phần tử mỗi trang; có đủ thông tin phân trang (page, size, total); các trang không trùng nhau (AC-SEARCH-002). | E19: Có > 10 chuyến phù hợp. | F19: Pending | I19: Pending | L19: Pending
A20: SRCH-08 | B20: Kích thước trang vượt giới hạn | C20: 1. GET /trips/search?size=100000 | D20: Bị giới hạn về mức tối đa cho phép hoặc trả 400; không trả toàn bộ dữ liệu (§7.4). | E20: - | F20: Pending | I20: Pending | L20: Pending
A21: Chi tiết chuyến xe & ghế trống
A22: SRCH-09 | B22: Xem chi tiết chuyến xe | C22: 1. GET /trips/{tripId} | D22: 200; có nhà xe, lịch trình, xe, tiện nghi, điểm đón/trả, giá và bản chụp chính sách đang áp dụng. | E22: Có chuyến T1. | F22: Pending | I22: Pending | L22: Pending
A23: SRCH-10 | B23: Xem chuyến không tồn tại | C23: 1. GET /trips/{id không tồn tại} | D23: 404 RESOURCE_NOT_FOUND; không có stack trace/thông tin hệ thống. | E23: - | F23: Pending | I23: Pending | L23: Pending
A24: SRCH-11 | B24: Số ghế trống kèm thời điểm cập nhật | C24: 1. GET /trips/{tripId}/seats 2. Đối chiếu số ghế AVAILABLE và trường thời điểm cập nhật | D24: Có số ghế trống và thời điểm cập nhật (FR-SEARCH-006). | E24: Có chuyến T1. | F24: Pending | I24: Pending | L24: Pending
A25: SRCH-12 | B25: Tham số tìm kiếm chứa payload SQL injection/XSS | C25: 1. GET /trips/search?from=' OR 1=1-- 2. GET /trips/search?from=<script>alert(1)</script> | D25: Không lỗi 500, không lộ lỗi SQL/tên bảng; dữ liệu trả về được mã hóa ký tự đặc biệt (NFR-SEC-007). | E25: - | F25: Pending | I25: Pending | L25: Pending
A26: Thông tin nhà xe
A27: OPS-01 | B27: Cập nhật thông tin nhà xe, bật/tắt trả sau | C27: 1. PUT /operators/me {payLaterEnabled:true} 2. GET /operators/me | D27: 200; thông tin được cập nhật đúng; dữ liệu gắn với nhà xe A. | E27: Operator Staff của nhà xe A đã đăng nhập. | F27: Pending | I27: Pending | L27: Pending
A28: OPS-02 | B28: Nhà xe đổi tỷ lệ phí sàn qua API nhà xe | C28: 1. PUT /operators/me {platformFeeRate:0} 2. GET /operators/me | D28: Bị từ chối hoặc bỏ qua; phí sàn không đổi (FR-OPS-011). | E28: Operator Staff của nhà xe A đã đăng nhập. | F28: Pending | I28: Pending | L28: Pending
A29: OPS-03 | B29: Nhân viên nhà xe A truy cập dữ liệu nhà xe B | C29: 1. PUT /operators/{orgId B} / gửi organizationId = B trong body 2. GET xe/tài xế/tuyến của B | D29: 403 ACCESS_DENIED / 404; không trả dữ liệu của B; orgId lấy từ ngữ cảnh định danh (AC-AUTH-002, AUTHZ-003). | E29: Operator Staff của nhà xe A đã đăng nhập. Có dữ liệu nhà xe B. | F29: Pending | I29: Pending | L29: Pending
A30: Xe & sơ đồ ghế
A31: OPS-04 | B31: Tạo xe và sơ đồ ghế hợp lệ | C31: 1. POST /buses {plateNumber, type, seatLayout} 2. GET /buses | D31: 201; xe gắn với nhà xe A; nhà xe B không thấy (AC-OPS-001). | E31: Operator Staff của nhà xe A đã đăng nhập. | F31: Pending | I31: Pending | L31: Pending
A32: OPS-05 | B32: Tạo xe với biển số trùng | C32: 1. POST /buses với plateNumber đã tồn tại | D32: Bị từ chối (409/400); không tạo bản ghi trùng. | E32: Operator Staff của nhà xe A đã đăng nhập. Đã có xe với biển số test. | F32: Pending | I32: Pending | L32: Pending
A33: OPS-06 | B33: Xóa xe đã được chuyến tham chiếu | C33: 1. DELETE /buses/{id} 2. GET /buses/{id} | D33: Không xóa cứng; chỉ vô hiệu hóa/xóa mềm (AC-OPS-002, FR-OPS-009). | E33: Operator Staff của nhà xe A đã đăng nhập. Xe đã gắn vào chuyến. | F33: Pending | I33: Pending | L33: Pending
A34: Tài xế
A35: OPS-07 | B35: Tạo tài xế hợp lệ | C35: 1. POST /drivers {name, phone, licenseNo, licenseExpiry còn hạn} | D35: 201; tài xế gắn với nhà xe A. | E35: Operator Staff của nhà xe A đã đăng nhập. | F35: Pending | I35: Pending | L35: Pending
A36: OPS-08 | B36: Tạo tài xế có giấy phép hết hạn | C36: 1. POST /drivers {licenseExpiry trong quá khứ} | D36: 400 VALIDATION_ERROR hoặc bị từ chối do giấy phép hết hạn (FR-OPS-003). | E36: Operator Staff của nhà xe A đã đăng nhập. | F36: Pending | I36: Pending | L36: Pending
A37: Tuyến & điểm dừng
A38: OPS-09 | B38: Tạo tuyến với các điểm dừng có thứ tự | C38: 1. POST /routes {stops:[{order,time}...]} 2. GET /routes/{id} | D38: 201; tuyến, thứ tự dừng và thời gian dự kiến được lưu đúng. | E38: Operator Staff của nhà xe A đã đăng nhập. | F38: Pending | I38: Pending | L38: Pending
A39: OPS-10 | B39: Tạo tuyến với thứ tự điểm dừng không hợp lệ | C39: 1. POST /routes với thứ tự trùng/không liên tục hoặc thời gian đảo ngược | D39: 400 VALIDATION_ERROR; không tạo tuyến. | E39: Operator Staff của nhà xe A đã đăng nhập. | F39: Pending | I39: Pending | L39: Pending
A40: OPS-11 | B40: Xóa tuyến đã được tham chiếu | C40: 1. DELETE /routes/{id} | D40: Không xóa cứng; chỉ vô hiệu hóa/xóa mềm (FR-OPS-009). | E40: Operator Staff của nhà xe A đã đăng nhập. Tuyến đã gắn vào chuyến. | F40: Pending | I40: Pending | L40: Pending
A41: Tạo & công bố chuyến
A42: TRIP-01 | B42: Tạo chuyến ở dạng nháp | C42: 1. POST /trips {routeId, busId, driverId, departureTime, price} 2. GET /trips/{id} | D42: 201; chuyến ở trạng thái DRAFT, chưa xuất hiện trong kết quả tìm kiếm. | E42: Operator Staff của nhà xe A đã đăng nhập. | F42: Pending | I42: Pending | L42: Pending
...

Sheet Booking_Service
A2: Feature | B2: Booking Service | R2: Passed
A3: Test requirement | B3: FR-BOOK-001..012, FR-TICKET-001..006, FR-PROMO-001/002, FR-REVIEW-001/002, BR-SEAT-001..010, BR-BOOK-001..012, BR-CANCEL-001..008, BR-TICKET-001..004, BR-REVIEW-001/002, AC-SEAT/BOOK/CANCEL/CHANGE/TICKET/PROMO/REVIEW: giữ ghế, đặt chỗ, hủy & đổi vé, vé điện tử, check-in, khuyến mãi, đánh giá. | R3: Failed
A4: Number of TCs | B4: =COUNTA(B11:B1000) -> 54 | R4: Pending
A5: Testing Round | B5: Passed | C5: Failed | D5: Pending | E5: N/A | R5: N/A
A6: Round 1 | B6: =COUNTIF($F$11:$F$1000,B$5) -> 0 | C6: =COUNTIF($F$11:$F$1000,C$5) -> 0 | D6: =COUNTIF($F$11:$F$1000,D$5) -> 54 | E6: =COUNTIF($F$11:$F$1000,E$5) -> 0
A7: Round 2 | B7: =COUNTIF($I$11:$I$1000,B$5) -> 0 | C7: =COUNTIF($I$11:$I$1000,C$5) -> 0 | D7: =COUNTIF($I$11:$I$1000,D$5) -> 54 | E7: =COUNTIF($I$11:$I$1000,E$5) -> 0
A8: Round 3 | B8: =COUNTIF($L$11:$L$1000,B$5) -> 0 | C8: =COUNTIF($L$11:$L$1000,C$5) -> 0 | D8: =COUNTIF($L$11:$L$1000,D$5) -> 54 | E8: =COUNTIF($L$11:$L$1000,E$5) -> 0
A10: Test Case ID | B10: Test Case Description | C10: Test Case Procedure | D10: Expected Results | E10: Pre-conditions | F10: Round 1 | G10: Test date | H10: Tester | I10: Round 2 | J10: Test date | K10: Tester | L10: Round 3 | M10: Test date | N10: Tester | O10: Note
A11: Xem ghế & giữ ghế (SeatHold)
A12: BOOK-01 | B12: Xem danh sách TripSeat và tình trạng | C12: 1. GET /trips/{tripId}/seats (có token) | D12: 200; trả danh sách ghế kèm trạng thái AVAILABLE/HELD/BOOKED/DISABLED. | E12: Customer đã đăng nhập (có accessToken). | F12: Pending | I12: Pending | L12: Pending
A13: BOOK-02 | B13: Giữ 1 ghế hợp lệ | C13: 1. POST /seat-holds {tripId, seatIds:[A1]} + header Idempotency-Key 2. GET seats | D13: 201; trả holdId/token, expiresAt, bản chụp giá; ghế A1 chuyển HELD. | E13: Customer đã đăng nhập (có accessToken). Có chuyến T1 đang mở bán, còn ghế AVAILABLE. | F13: Pending | I13: Pending | L13: Pending
A14: BOOK-03 | B14: Giữ nhiều ghế hợp lệ trong cùng yêu cầu | C14: 1. POST /seat-holds {seatIds:[A1,A2]} | D14: 201; cả 2 ghế HELD, cùng 1 SeatHold. | E14: Customer đã đăng nhập (có accessToken). Có chuyến T1 đang mở bán, còn ghế AVAILABLE. | F14: Pending | I14: Pending | L14: Pending
A15: BOOK-04 | B15: Giữ nhiều ghế khi có 1 ghế không còn trống (all-or-nothing) | C15: 1. Customer 2 giữ A2 2. Customer 1 POST /seat-holds {seatIds:[A1,A2]} 3. GET seats | D15: 409 SEAT_UNAVAILABLE kèm seat code bị ảnh hưởng; toàn bộ yêu cầu thất bại, A1 vẫn AVAILABLE (AC-SEAT-002). | E15: A1 AVAILABLE, A2 đã HELD/BOOKED. | F15: Pending | I15: Pending | L15: Pending
A16: BOOK-05 | B16: Hai khách giữ cùng 1 ghế đồng thời | C16: 1. Gửi đồng thời 2 request POST /seat-holds ghế A1 từ 2 Customer khác nhau (Runner/Newman song song) 2. Kiểm tra kết quả | D16: Đúng 1 request thành công; request còn lại 409 SEAT_UNAVAILABLE; không bán trùng ghế (AC-SEAT-001, NFR-PERF-007). | E16: A1 AVAILABLE; 2 Customer đã đăng nhập. | F16: Pending | I16: Pending | L16: Pending
A17: BOOK-06 | B17: Giữ ghế khi chưa đăng nhập | C17: 1. POST /seat-holds không gửi token | D17: 401 AUTHENTICATION_REQUIRED; không tạo SeatHold (BR-BOOK-001). | E17: - | F17: Pending | I17: Pending | L17: Pending
A18: BOOK-07 | B18: Giữ ghế của chuyến không còn bán | C18: 1. POST /seat-holds với chuyến CANCELLED/DEPARTED | D18: 409 TRIP_NOT_SELLABLE; không tạo SeatHold. | E18: Có chuyến đã CANCELLED hoặc DEPARTED. | F18: Pending | I18: Pending | L18: Pending
A19: BOOK-08 | B19: Gửi lặp cùng Idempotency-Key và cùng nội dung | C19: 1. POST /seat-holds (key K, body B) 2. Gửi lại đúng key K, body B | D19: Trả lại đúng SeatHold đã tạo; không tạo SeatHold mới (BR-SEAT-007). | E19: Customer đã đăng nhập (có accessToken). Có chuyến T1 đang mở bán, còn ghế AVAILABLE. | F19: Pending | I19: Pending | L19: Pending
A20: BOOK-09 | B20: SeatHold hết hạn được giải phóng tự động | C20: 1. Giữ ghế A1 2. Chờ quá expiresAt 3. GET seats | D20: SeatHold chuyển EXPIRED; ghế A1 trở về AVAILABLE (FR-BOOK-007, BR-SEAT-008). | E20: Đã có SeatHold ACTIVE; biết timeout cấu hình. | F20: Pending | I20: Pending | L20: Pending
A21: Tạo đơn đặt chỗ (Booking)
A22: BOOK-10 | B22: Tạo booking PREPAID từ SeatHold hợp lệ | C22: 1. POST /bookings {holdId, passengers[1 người/ghế], paymentChannel:PREPAID} + Idempotency-Key | D22: 201; booking PENDING_PAYMENT; backend tính tạm tính, giảm giá, phí, tổng tiền; SeatHold chuyển CONSUMED. | E22: Customer đã đăng nhập (có accessToken). Có SeatHold ACTIVE. | F22: Pending | I22: Pending | L22: Pending
A23: BOOK-11 | B23: Backend bỏ qua tổng tiền do client gửi | C23: 1. POST /bookings kèm totalAmount nhỏ hơn giá trong bản chụp | D23: Server bỏ qua giá trị client, tính lại và trả tổng tiền chính thức (AC-BOOK-001, BR-BOOK-004). | E23: Customer đã đăng nhập (có accessToken). Có SeatHold ACTIVE. | F23: Pending | I23: Pending | L23: Pending
A24: BOOK-12 | B24: Tạo booking lặp cùng key và cùng nội dung | C24: 1. POST /bookings (key K, body B) 2. Gửi lại nhiều lần cùng K, B | D24: Chỉ có 1 booking; các phản hồi tham chiếu cùng bookingId (AC-BOOK-002). | E24: Customer đã đăng nhập (có accessToken). Có SeatHold ACTIVE. | F24: Pending | I24: Pending | L24: Pending
A25: BOOK-13 | B25: Cùng Idempotency-Key nhưng nội dung khác | C25: 1. POST /bookings (key K, body B) 2. POST /bookings (key K, body B' khác) | D25: 409 IDEMPOTENCY_CONFLICT; không phát sinh tác động mới (AC-BOOK-003). | E25: Customer đã đăng nhập (có accessToken). Có SeatHold ACTIVE. | F25: Pending | I25: Pending | L25: Pending
A26: BOOK-14 | B26: Số hành khách khác số ghế | C26: 1. POST /bookings với số passengers ≠ số ghế trong SeatHold | D26: 400 VALIDATION_ERROR; không tạo booking, SeatHold không bị sử dụng (AC-BOOK-004). | E26: Customer đã đăng nhập (có accessToken). Có SeatHold ACTIVE 2 ghế. | F26: Pending | I26: Pending | L26: Pending
A27: BOOK-15 | B27: Thiếu thông tin bắt buộc của hành khách | C27: 1. POST /bookings với passenger thiếu họ tên/SĐT (theo chính sách chuyến) | D27: 400 VALIDATION_ERROR kèm field lỗi; không tạo booking. | E27: Customer đã đăng nhập (có accessToken). Có SeatHold ACTIVE. | F27: Pending | I27: Pending | L27: Pending
A28: BOOK-16 | B28: Tạo booking từ SeatHold đã hết hạn | C28: 1. Chờ SeatHold quá expiresAt 2. POST /bookings {holdId} | D28: 410 SEAT_HOLD_EXPIRED; không tạo booking; ghế hợp lệ được giải phóng (AC-SEAT-003). | E28: SeatHold đã quá hạn. | F28: Pending | I28: Pending | L28: Pending
A29: BOOK-17 | B29: Dùng SeatHold của người khác / dùng 1 SeatHold cho 2 booking | C29: 1. Customer 2 POST /bookings với holdId của Customer 1 2. Customer 1 tạo booking lần 1 rồi lần 2 (key khác) cùng holdId | D29: Trường hợp 1: 403/404, không lộ dữ liệu. Trường hợp 2: lần 2 bị từ chối (BR-BOOK-002). | E29: Có SeatHold của Customer 1. | F29: Pending | I29: Pending | L29: Pending
A30: BOOK-18 | B30: Tạo booking PAY_LATER khi nhà xe bật trả sau | C30: 1. POST /bookings {paymentChannel:PAY_LATER} 2. Kiểm tra booking, vé, ghế, payment | D30: Booking CONFIRMED; mỗi mục 1 vé PAY_LATER; ghế BOOKED; không tạo thanh toán qua cổng (AC-BOOK-007, FR-BOOK-012). | E30: Nhà xe bật cho phép trả sau; SeatHold còn hạn. | F30: Pending | I30: Pending | L30: Pending
A31: BOOK-19 | B31: Tạo booking PAY_LATER khi nhà xe tắt trả sau | C31: 1. POST /bookings {paymentChannel:PAY_LATER} | D31: 409 PAY_LATER_NOT_ALLOWED; không tạo booking, SeatHold không bị sử dụng (AC-BOOK-006). | E31: Nhà xe tắt trả sau. | F31: Pending | I31: Pending | L31: Pending
A32: BOOK-20 | B32: paymentChannel không hợp lệ | C32: 1. POST /bookings {paymentChannel:"COD"} | D32: 400 VALIDATION_ERROR; chỉ chấp nhận PREPAID hoặc PAY_LATER (BR-BOOK-011). | E32: Customer đã đăng nhập (có accessToken). Có SeatHold ACTIVE. | F32: Pending | I32: Pending | L32: Pending
A33: BOOK-21 | B33: Booking PREPAID quá hạn thanh toán chuyển EXPIRED | C33: 1. Tạo booking PREPAID, không thanh toán 2. Chờ quá hạn 3. GET /bookings/{id} 4. GET seats | D33: Booking EXPIRED; ghế được giải phóng về AVAILABLE (BR-BOOK-007, FR-BOOK-007). | E33: Có booking PENDING_PAYMENT; biết thời hạn cấu hình. | F33: Pending | I33: Pending | L33: Pending
A34: Xem đơn đặt chỗ của tôi
A35: BOOK-22 | B35: Xem danh sách đơn/vé của chính mình | C35: 1. GET /bookings/my (lọc theo trạng thái: sắp đi, đã dùng, đã hủy, đã hoàn tiền) | D35: 200; chỉ trả booking/vé của Customer đang đăng nhập, đúng theo bộ lọc. | E35: Customer đã đăng nhập (có accessToken). Có nhiều booking. | F35: Pending | I35: Pending | L35: Pending
A36: BOOK-23 | B36: Xem booking của khách khác khi biết mã | C36: 1. Customer A GET /bookings/{bookingId của B} | D36: Bị từ chối (403/404), không lộ dữ liệu của B (AC-BOOK-005, AUTHZ-004). | E36: Có booking của Customer B. | F36: Pending | I36: Pending | L36: Pending
A37: BOOK-24 | B37: Xem booking không tồn tại | C37: 1. GET /bookings/{id không tồn tại} | D37: 404 RESOURCE_NOT_FOUND. | E37: Customer đã đăng nhập (có accessToken). | F37: Pending | I37: Pending | L37: Pending
A38: Hủy vé & hoàn tiền
A39: CAN-01 | B39: Xem trước hủy vé PREPAID | C39: 1. POST /tickets/{id}/cancel-preview | D39: 200; có phiên bản chính sách, phí hủy, số tiền hoàn trước khi xác nhận (AC-CANCEL-001, BR-CANCEL-002). | E39: Có booking PREPAID đã PAID, vé ISSUED. | F39: Pending | I39: Pending | L39: Pending
A40: CAN-02 | B40: Xác nhận hủy vé PREPAID | C40: 1. POST /tickets/{id}/cancel + Idempotency-Key 2. GET ticket, booking, refund, seats | D40: Vé CANCELLED; tạo refund; booking CANCELLED → REFUND_PENDING; ghế về AVAILABLE nếu chuyến còn cho bán (BR-CANCEL-005). | E40: Có booking PREPAID đã PAID, vé ISSUED. | F40: Pending | I40: Pending | L40: Pending
A41: CAN-03 | B41: Hủy vé PAY_LATER không hoàn tiền qua cổng | C41: 1. POST cancel-preview cho vé PAY_LATER 2. POST cancel xác nhận | D41: Số tiền hoàn = 0; vé/booking CANCELLED; không tạo refund qua cổng (FR-BOOK-009, FR-PAY-011). | E41: Có booking PAY_LATER CONFIRMED. | F41: Pending | I41: Pending | L41: Pending
A42: CAN-04 | B42: Gửi lặp lệnh hủy cùng key | C42: 1. POST cancel (key K) 2. Gửi lại cùng key K 3. Đếm refund | D42: Không tạo refund thứ hai (AC-CANCEL-002). | E42: Có booking PREPAID đã PAID, vé ISSUED. | F42: Pending | I42: Pending | L42: Pending
...

Sheet Payment_Service
A2: Feature | B2: Payment Service | R2: Passed
A3: Test requirement | B3: FR-PAY-001..007/012/013, BR-PAY-001..014, AC-PAY-001..008, NFR-PERF-005: payment intent, webhook, settlement. | R3: Failed
A4: Number of TCs | B4: =COUNTA(B11:B1000) -> 13 | R4: Pending
A5: Testing Round | B5: Passed | C5: Failed | D5: Pending | E5: N/A | R5: N/A
A6: Round 1 | B6: =COUNTIF($F$11:$F$1000,B$5) -> 0 | C6: =COUNTIF($F$11:$F$1000,C$5) -> 0 | D6: =COUNTIF($F$11:$F$1000,D$5) -> 13 | E6: =COUNTIF($F$11:$F$1000,E$5) -> 0
A7: Round 2 | B7: =COUNTIF($I$11:$I$1000,B$5) -> 0 | C7: =COUNTIF($I$11:$I$1000,C$5) -> 0 | D7: =COUNTIF($I$11:$I$1000,D$5) -> 13 | E7: =COUNTIF($I$11:$I$1000,E$5) -> 0
A8: Round 3 | B8: =COUNTIF($L$11:$L$1000,B$5) -> 0 | C8: =COUNTIF($L$11:$L$1000,C$5) -> 0 | D8: =COUNTIF($L$11:$L$1000,D$5) -> 13 | E8: =COUNTIF($L$11:$L$1000,E$5) -> 0
A10: Test Case ID | B10: Test Case Description | C10: Test Case Procedure | D10: Expected Results | E10: Pre-conditions | F10: Round 1 | G10: Test date | H10: Tester | I10: Round 2 | J10: Test date | K10: Tester | L10: Round 3 | M10: Test date | N10: Tester | O10: Note
A11: Tạo yêu cầu thanh toán
A12: PAY-01 | B12: Tạo payment intent cho booking PREPAID hợp lệ | C12: 1. POST /payments {bookingId} + Idempotency-Key | D12: 201; payment ở PENDING/PROCESSING; trả paymentUrl; request gửi cổng có mã tham chiếu duy nhất, số tiền, tiền tệ, callback. | E12: Có booking PREPAID ở PENDING_PAYMENT (còn hạn) của Customer. | F12: Pending | I12: Pending | L12: Pending
A13: PAY-02 | B13: Tạo payment cho booking PAY_LATER | C13: 1. POST /payments {bookingId của đơn PAY_LATER} | D13: Bị từ chối; không tạo thanh toán qua cổng (AC-PAY-007). | E13: Có booking PAY_LATER CONFIRMED. | F13: Pending | I13: Pending | L13: Pending
A14: PAY-03 | B14: Tạo payment cho booking đã hết hạn | C14: 1. POST /payments {bookingId EXPIRED} | D14: 410 BOOKING_EXPIRED; không tạo Payment mới. | E14: Có booking EXPIRED. | F14: Pending | I14: Pending | L14: Pending
A15: PAY-04 | B15: Tạo payment cho booking của khách khác | C15: 1. Customer A POST /payments {bookingId của B} | D15: 403 ACCESS_DENIED / 404; không lộ dữ liệu. | E15: Có booking PREPAID của Customer B. | F15: Pending | I15: Pending | L15: Pending
A16: Webhook thanh toán
A17: PAY-05 | B17: Webhook thành công hợp lệ | C17: 1. POST /payments/webhook (chữ ký đúng, số tiền + tiền tệ khớp) 2. GET booking, seats, tickets | D17: 200 trong ≤ 2s (p95); Payment SUCCEEDED, booking PAID, ghế BOOKED, mỗi mục 1 vé (AC-PAY-001, NFR-PERF-005). | E17: Có booking PREPAID ở PENDING_PAYMENT (còn hạn) của Customer. Đã tạo payment. | F17: Pending | I17: Pending | L17: Pending
A18: PAY-06 | B18: Webhook gửi lặp | C18: 1. POST cùng webhook (cùng mã sự kiện) nhiều lần 2. Đếm payment và vé | D18: Chỉ có 1 payment thành công và 1 bộ vé; lần gửi lặp không tạo thay đổi thứ hai (AC-PAY-002, BR-PAY-003). | E18: Có booking PREPAID ở PENDING_PAYMENT (còn hạn) của Customer. Đã tạo payment. | F18: Pending | I18: Pending | L18: Pending
A19: PAY-07 | B19: Webhook sai chữ ký | C19: 1. POST /payments/webhook với chữ ký sai/thiếu | D19: Bị từ chối; booking không PAID, không có vé; ghi log bảo mật an toàn (BR-PAY-005). | E19: Có booking PREPAID ở PENDING_PAYMENT (còn hạn) của Customer. Đã tạo payment. | F19: Pending | I19: Pending | L19: Pending
A20: PAY-08 | B20: Webhook sai số tiền hoặc sai loại tiền tệ | C20: 1. POST webhook với amount khác payment intent 2. POST webhook với currency khác | D20: 422 PAYMENT_VERIFICATION_FAILED; booking không PAID, không tạo vé; có hồ sơ đối soát/bảo mật (AC-PAY-003, BR-PAY-004). | E20: Có booking PREPAID ở PENDING_PAYMENT (còn hạn) của Customer. Đã tạo payment. | F20: Pending | I20: Pending | L20: Pending
A21: PAY-09 | B21: Webhook thanh toán thất bại / bị hủy | C21: 1. POST webhook trạng thái FAILED 2. POST webhook trạng thái CANCELLED | D21: Booking không chuyển PAID; không phát hành vé (AC-PAY-006); ghế giữ đến hết hạn hoặc giải phóng theo quy tắc. | E21: Có booking PREPAID ở PENDING_PAYMENT (còn hạn) của Customer. Đã tạo payment. | F21: Pending | I21: Pending | L21: Pending
A22: PAY-10 | B22: Webhook thành công đến trễ khi ghế đã thuộc đơn khác | C22: 1. Để booking hết hạn, ghế được đơn khác mua 2. POST webhook thành công cho payment cũ | D22: Không bán trùng ghế; tạo hoàn tiền bù trừ hoặc hồ sơ xử lý thủ công (AC-PAY-004, BR-PAY-006). | E22: Booking đã EXPIRED, ghế đã BOOKED bởi đơn khác. | F22: Pending | I22: Pending | L22: Pending
A23: PAY-11 | B23: Xem trạng thái khi webhook chưa đến / chỉ có redirect | C23: 1. Gọi return-callback từ cổng (không webhook) 2. GET /payments/{id} | D23: Trả PROCESSING (202 PAYMENT_PROCESSING), booking vẫn PENDING_PAYMENT; redirect không được coi là đã thanh toán (AC-PAY-005, BR-PAY-010). | E23: Có booking PREPAID ở PENDING_PAYMENT (còn hạn) của Customer. Đã tạo payment. | F23: Pending | I23: Pending | L23: Pending
A24: Settlement & dữ liệu nhạy cảm
A25: PAY-12 | B25: Chốt phí sàn 10% khi PREPAID thành công | C25: 1. Thanh toán PREPAID tổng 100000 (phí sàn nhà xe 10%) 2. GET settlement của booking | D25: Phí sàn 10000; nhà xe thực nhận (operator_net) 90000; trạng thái thu COLLECTED (AC-PAY-008). | E25: Nhà xe có phí sàn 10%; booking PAID 100000. | F25: Pending | I25: Pending | L25: Pending
A26: PAY-13 | B26: Không lưu/không trả số thẻ (PAN) và CVV | C26: 1. Thực hiện thanh toán 2. GET /payments/{id}, kiểm tra toàn bộ response | D26: Response không chứa PAN/CVV; chỉ có token/mã tham chiếu (BR-PAY-009). | E26: Có booking PREPAID đã PAID, vé ISSUED. | F26: Pending | I26: Pending | L26: Pending

Sheet Notification_Service
A2: Feature | B2: Notification Service | R2: Passed
A3: Test requirement | B3: FR-NOTIF-001..003 (SHOULD/MUST), AC-NOTIF-001/002: tạo thông báo theo sự kiện nghiệp vụ, cấu hình kênh, lỗi nhà cung cấp thông báo. | R3: Failed
A4: Number of TCs | B4: =COUNTA(B11:B1000) -> 3 | R4: Pending
A5: Testing Round | B5: Passed | C5: Failed | D5: Pending | E5: N/A | R5: N/A
A6: Round 1 | B6: =COUNTIF($F$11:$F$1000,B$5) -> 0 | C6: =COUNTIF($F$11:$F$1000,C$5) -> 0 | D6: =COUNTIF($F$11:$F$1000,D$5) -> 3 | E6: =COUNTIF($F$11:$F$1000,E$5) -> 0
A7: Round 2 | B7: =COUNTIF($I$11:$I$1000,B$5) -> 0 | C7: =COUNTIF($I$11:$I$1000,C$5) -> 0 | D7: =COUNTIF($I$11:$I$1000,D$5) -> 3 | E7: =COUNTIF($I$11:$I$1000,E$5) -> 0
A8: Round 3 | B8: =COUNTIF($L$11:$L$1000,B$5) -> 0 | C8: =COUNTIF($L$11:$L$1000,C$5) -> 0 | D8: =COUNTIF($L$11:$L$1000,D$5) -> 3 | E8: =COUNTIF($L$11:$L$1000,E$5) -> 0
A10: Test Case ID | B10: Test Case Description | C10: Test Case Procedure | D10: Expected Results | E10: Pre-conditions | F10: Round 1 | G10: Test date | H10: Tester | I10: Round 2 | J10: Test date | K10: Tester | L10: Round 3 | M10: Test date | N10: Tester | O10: Note
A11: Thông báo
A12: NOTIF-01 | B12: Tạo thông báo khi sự kiện nghiệp vụ xảy ra | C12: 1. Thanh toán thành công booking 2. GET /notifications | D12: Có thông báo thanh toán/phát hành vé (FR-NOTIF-001); chỉ của chính người dùng. | E12: Có booking PREPAID ở PENDING_PAYMENT (còn hạn) của Customer. | F12: Pending | I12: Pending | L12: Pending
A13: NOTIF-02 | B13: Cấu hình kênh thông báo | C13: 1. PUT /notifications/preferences tắt kênh tùy chọn 2. PUT tắt thông báo giao dịch thiết yếu | D13: Kênh tùy chọn được tắt; thông báo thiết yếu không thể tắt hoàn toàn (AC-NOTIF-002). | E13: Customer đã đăng nhập (có accessToken). | F13: Pending | I13: Pending | L13: Pending
A14: NOTIF-03 | B14: Nhà cung cấp thông báo lỗi không hoàn tác giao dịch | C14: 1. Cấu hình provider mock lỗi 2. Thanh toán booking thành công 3. Kiểm tra booking, vé, hàng đợi retry | D14: Booking/thanh toán đã chốt không bị hoàn tác; thông báo được retry theo chính sách (AC-NOTIF-001, FR-NOTIF-002). | E14: Có booking PREPAID ở PENDING_PAYMENT (còn hạn) của Customer. Provider mock lỗi. | F14: Pending | I14: Pending | L14: Pending

Sheet Report_Service
A2: Feature | B2: Report Service | R2: Passed
A3: Test requirement | B3: FR-ADMIN-002/003, FR-REPORT-001..003, BR-AUDIT-001/002, AC-ADMIN-003/004, AC-REPORT-001/002: tra cứu giao dịch, kiểm toán, khiếu nại, báo cáo và xuất dữ liệu. | R3: Failed
A4: Number of TCs | B4: =COUNTA(B11:B1000) -> 7 | R4: Pending
A5: Testing Round | B5: Passed | C5: Failed | D5: Pending | E5: N/A | R5: N/A
A6: Round 1 | B6: =COUNTIF($F$11:$F$1000,B$5) -> 0 | C6: =COUNTIF($F$11:$F$1000,C$5) -> 0 | D6: =COUNTIF($F$11:$F$1000,D$5) -> 7 | E6: =COUNTIF($F$11:$F$1000,E$5) -> 0
A7: Round 2 | B7: =COUNTIF($I$11:$I$1000,B$5) -> 0 | C7: =COUNTIF($I$11:$I$1000,C$5) -> 0 | D7: =COUNTIF($I$11:$I$1000,D$5) -> 7 | E7: =COUNTIF($I$11:$I$1000,E$5) -> 0
A8: Round 3 | B8: =COUNTIF($L$11:$L$1000,B$5) -> 0 | C8: =COUNTIF($L$11:$L$1000,C$5) -> 0 | D8: =COUNTIF($L$11:$L$1000,D$5) -> 7 | E8: =COUNTIF($L$11:$L$1000,E$5) -> 0
A10: Test Case ID | B10: Test Case Description | C10: Test Case Procedure | D10: Expected Results | E10: Pre-conditions | F10: Round 1 | G10: Test date | H10: Tester | I10: Round 2 | J10: Test date | K10: Tester | L10: Round 3 | M10: Test date | N10: Tester | O10: Note
A11: Tra cứu giao dịch, kiểm toán & khiếu nại
A12: ADM-06 | B12: Tra cứu booking/payment/refund bằng mã | C12: 1. GET /admin/transactions?code={bookingCode|paymentId|refundId} | D12: Liên kết được giao dịch và nhật ký kiểm toán; không có chức năng sửa lịch sử (AC-ADMIN-003). | E12: Admin đã đăng nhập. Có giao dịch mẫu. | F12: Pending | I12: Pending | L12: Pending
A13: ADM-07 | B13: Sửa/xóa bản ghi nhật ký kiểm toán | C13: 1. PUT /admin/audit-logs/{id} 2. DELETE /admin/audit-logs/{id} | D13: Bị từ chối (405/403); audit chỉ thêm mới (BR-AUDIT-002). | E13: Admin đã đăng nhập. | F13: Pending | I13: Pending | L13: Pending
A14: ADM-08 | B14: Đóng khiếu nại thiếu kết quả xử lý (SHOULD) | C14: 1. PATCH /admin/complaints/{id}/close không có resolution | D14: Bị từ chối; khiếu nại vẫn mở (AC-ADMIN-004). | E14: Admin đã đăng nhập. Có khiếu nại đang mở. | F14: Pending | I14: Pending | L14: Pending
A15: Báo cáo & xuất dữ liệu
A16: REP-01 | B16: Admin xem báo cáo theo khoảng thời gian | C16: 1. GET /reports/summary?from=&to= 2. Đối chiếu với dữ liệu giao dịch mẫu | D16: Trả tổng thu, thực nhận, phí sàn, số đơn, hoàn tiền, tỷ lệ lấp đầy; có định nghĩa chỉ số và múi giờ (FR-REPORT-001). | E16: Admin đã đăng nhập. Có dữ liệu giao dịch mẫu. | F16: Pending | I16: Pending | L16: Pending
A17: REP-02 | B17: Nhân viên tài chính nhà xe A chỉ thấy dữ liệu nhà xe A | C17: 1. Finance Staff A GET /reports/summary 2. Thử truyền organizationId = B | D17: Chỉ có dữ liệu nhà xe A; tham số org B bị bỏ qua/từ chối; hiển thị chỉ số, múi giờ, độ mới dữ liệu (AC-REPORT-001). | E17: Finance Staff nhà xe A đã đăng nhập. | F17: Pending | I17: Pending | L17: Pending
A18: REP-03 | B18: Xuất báo cáo lớn bất đồng bộ (SHOULD) | C18: 1. POST /reports/export (khoảng dữ liệu lớn) 2. GET trạng thái job 3. Tải file bằng user khác quyền | D18: Tạo export job, thông báo khi sẵn sàng; kiểm tra lại quyền khi tải, user không có quyền bị từ chối (AC-REPORT-002). | E18: Admin đã đăng nhập. | F18: Pending | I18: Pending | L18: Pending
A19: REP-04 | B19: Khoảng thời gian báo cáo không hợp lệ | C19: 1. GET /reports/summary?from=2026-10-30&to=2026-10-01 | D19: 400 VALIDATION_ERROR. | E19: Admin đã đăng nhập. | F19: Pending | I19: Pending | L19: Pending
